Workbook

Sheet Guide
A1: OPERF / TPG PARTNERS VI — GP/LP COMPENSATION MODEL
A2: Case: "Oregon Public Employees Retirement Fund: Push and Pull Over GP/LP Compensation" (Darden UV5622). Preparation Questions 3–6.
A3: Built on the layout of the Template sheet in the supplementary spreadsheet (UV5624-XLS-ENG.xlsx). $ millions unless stated.
A5: Model status
A6: Integrity checks | C6: =IF(AND('Q3 Base case'!$C$72="OK",'Q4 Fee cut'!$C$72="OK",'Q5a Hard hurdle'!$C$72="OK",'Q5b Soft hurdle'!$C$72="OK",'Q5c Lower carry'!$C$72="OK",Engine!$U$177=0,SUM(Summary!$B$36:$F$36)=0,'Q4 Analysis'!$C$26=0),"ALL CHECKS OK","CHECK THE MODEL") -> ALL CHECKS OK
A7: Base-case LP net IRR | C7: =Summary!$B$11 -> 0.15722559
A8: LP IRR with TPG offer | C8: =Summary!$C$11 -> 0.15936141
A10: Sheet map
A11: Sheet | B11: Prep question | C11: What it shows | D11: Presenter
A12: Inputs | B12: All | C12: Every assumption in one place (blue cells). Change here only. | D12: Shared
A13: Summary | B13: Q3–Q5 | C13: All scenarios side by side for LPs, TPG and OPERF, plus two charts and auto-updating talking points. | D13: Shared
A14: Q1-Q2 Context | B14: Q1–Q2 | C14: Case facts for the motivation and fee-vs-carry slides: what the offer costs TPG, fundraising and IPO data, LP sentiment, pay mix. | D14: Li (Parts 2–3)
A15: Q3 Base case | B15: Q3 | C15: Template model: current terms (1.50% fee, 20% carry). Year-by-year assets, waterfall, cash flows, IRR/NPV. | D15: Alex (Part 4)
A16: Q3 Analysis | B16: Q3 | C16: Gross-to-net bridge, who captures the value, fixed vs performance pay, fee growth with fund size. | D16: Alex (Part 4)
A17: Q4 Fee cut | B17: Q4 | C17: Template model with the 1.35% fee. | D17: Alex (Part 4)
A18: Q4 Analysis | B18: Q4 | C18: Fee cut vs current terms for the fund and for OPERF; fee saving vs extra carry; gain across outcomes. | D18: Alex (Part 4)
A19: Q5a Hard hurdle | B19: Q5 | C19: Template model: TPG offer + 8% preferred return, no catch-up. | D19: Jimmy (Part 5)
A20: Q5b Soft hurdle | B20: Q5 | C20: Template model: TPG offer + 8% preferred return with 100% GP catch-up. | D20: Jimmy (Part 5)
A21: Q5c Lower carry | B21: Q5 | C21: Template model: TPG offer + 15% carry. | D21: Jimmy (Part 5)
A22: Q5 Analysis | B22: Q5 | C22: Hurdle vs carry cut: base-case value, fee-equivalent, downside protection, carry earned in weak outcomes. | D22: Jimmy (Part 5)
... A25: Engine | B25: — | C25: Same model in one row per scenario (feeds the sensitivity tables). Reconciled to the template sheets. | D25: —
A27: Modelling conventions
A28: 1. | B28: Fund: $20bn committed, drawn in five equal 20% instalments at the start of Years 1–5 (Prep Q3).
A29: 2. | B29: Management fee = fee rate × committed capital, paid at the start of every year (Years 1–10) out of drawn capital / fund assets, exactly as the template does: Assets + Takedown − Fee = Invested capital.
A30: 3. | B30: Invested capital grows 20% during the year. From the end of Year 5, 20% of NAV is distributed each year; everything left is liquidated at the end of Year 10.
A31: 4. | B31: Whole-fund waterfall: (1) LPs get back all contributed capital, including the part used for fees; (2) preferred return, if any; (3) GP catch-up, soft hurdle only; (4) the rest split 80/20 (or 85/15).
A32: 5. | B32: Hurdle = 8% a year compounded on unreturned capital and unpaid preferred return, i.e. LPs must earn an 8% IRR before carry. Hard: carry only on profits above that. Soft: the GP takes 100% of distributions after the hurdle until it has 20% of all profits.
A33: 6. | B33: Timing: in the cash-flow rows each column is a point in time t; the start of Year n is t = n − 1. IRR and NPV use LP net cash flows; GP PV uses fees (start of year) and carry (end of year), all at 15%.
A34: 7. | B34: TPG's own ~$500m commitment is ignored (all capital is treated as LP capital). OPERF gets 750 ÷ 20,000 = 3.75% of LP cash flows.
A35: 8. | B35: TPG's 30% cap on 2009 capital calls is not binding in this model (draws are 20% a year).
A37: Colour code
A38: Input | B38: Blue text = hardcoded input (yellow fill = key lever)
A39: Formula | B39: Black text = calculation on the same sheet
A40: Link | B40: Green text = pulled from another sheet
A41: Section header | B41: Red bold italic = section header (template style)

Sheet Inputs
A1: MODEL INPUTS — OPERF / TPG PARTNERS VI
A2: Change blue cells here; every scenario sheet, table and chart updates. Yellow = the key levers for Q3–Q6.
A3: Colour code: blue = input · black = formula · green = linked from another sheet · red italic = section header (as in the Darden template)
A5: Fund assumptions (Preparation Question 3)
A6: Committed capital ($ millions) | C6: 20000 | D6: Prep Q3 assumption (case: TPG VI final close was $19.8bn)
A7: Fund life (years) | C7: =COLUMNS(C13:L13) -> 10 | D7: Model is built for a 10-year life (fee charged in each year)
A8: Annual growth rate of invested assets | C8: 0.2 | D8: Prep Q3 assumption
A9: Discount rate for fund cash flows | C9: 0.15 | D9: Prep Q3 assumption
A11: Drawdown and distribution schedule
A12: Year | B12: 0 | C12: 1 | D12: 2 | E12: 3 | F12: 4 | G12: 5 | H12: 6 | I12: 7 | J12: 8 | K12: 9 | L12: 10
A13: % of committed capital drawn (start of year) | C13: 0.2 | D13: 0.2 | E13: 0.2 | F13: 0.2 | G13: 0.2 | H13: 0 | I13: 0 | J13: 0 | K13: 0 | L13: 0
A14: Distribution rate (% of NAV, end of year) | C14: 0 | D14: 0 | E14: 0 | F14: 0 | G14: 0.2 | H14: 0.2 | I14: 0.2 | J14: 0.2 | K14: 0.2 | L14: 1
A15: Check: total drawn (must be 100%) | C15: =SUM(C13:L13) -> 1 | D15: Prep Q3: five equal draws at the start of Years 1–5; 20% of the portfolio liquidated from end of Year 5; all remaining assets at end of Year 10
A17: GP compensation terms
A18: Current management fee (% of committed capital, paid annually in advance) | C18: 0.015 | D18: Prep Q3; case p.1
A19: TPG proposed management fee | C19: 0.0135 | D19: TPG letter, Dec 2008 (case p.1)
A20: Carried interest — current (GP share of profits) | C20: 0.2 | D20: Standard 80/20 split (case p.4)
A21: Carried interest — OPERF counter-proposal | C21: 0.15 | D21: Prep Q5
A22: Hurdle (preferred return) — OPERF counter-proposal | C22: 0.08 | D22: Prep Q5
A23: GP catch-up in the soft-hurdle variant (1 = 100% catch-up, 0 = none) | C23: 1 | D23: Modelling choice: typical buyout-fund term; the hard-hurdle variant uses no catch-up
A25: OPERF position (case data)
A26: OPERF commitment to TPG VI ($ millions) | C26: 750 | D26: Case p.1 and p.5; Exhibit 7
A27: Commitment reduction offered by TPG | C27: 0.1 | D27: Case p.1 ($75m for OPERF)
A28: TPG VI capital contributed by OPERF to date ($ millions) | C28: 79.9 | D28: Exhibit 7
A29: TPG VI distributions to OPERF to date ($ millions) | C29: 0.6 | D29: Exhibit 7
A30: TPG VI fair market value of OPERF stake ($ millions) | C30: 47.5 | D30: Exhibit 7
A31: Max share of commitment TPG may call in 2009 | C31: 0.3 | D31: Case p.1
A32: OPERF total fund value, Dec 2008 ($ millions) | C32: 45800 | D32: Case p.4
A33: OPERF private equity allocation, Dec 2008 ($ millions) | C33: 9800 | D33: Case p.4
A34: Private equity actual allocation, 4Q 2008 | C34: 0.219 | D34: Case p.5; Exhibit 9
A35: Private equity target allocation | C35: 0.16 | D35: Case p.5; Exhibit 9
A37: Sensitivity grid (used by the Engine and Sensitivity sheets)
A38: Asset growth grid — start | C38: 0
A39: Asset growth grid — step | C39: 0.01 | D39: Keep the step at 1% so the Q6 two-way table can look up growth rates such as 18% or 22%
A40: Asset growth grid — end (31 points, fixed) | C40: =C38+30*C39 -> 0.3

Sheet Summary
A1: SCENARIO SUMMARY — what each set of terms means for LPs, TPG and OPERF
A2: Whole-fund figures in $ millions; LP = all limited partners together. Each column links to its template-style scenario sheet.
A4: Metric | B4: Current terms (Q3 base case) | C4: TPG offer (Q4: fee 1.35%) | D4: Offer + 8% hard hurdle (Q5a) | E4: Offer + 8% soft hurdle (Q5b) | F4: Offer + 15% carry (Q5c)
A5: Management fee (% of committed capital) | B5: ='Q3 Base case'!$C$3 -> 0.015 | C5: ='Q4 Fee cut'!$C$3 -> 0.0135 | D5: ='Q5a Hard hurdle'!$C$3 -> 0.0135 | E5: ='Q5b Soft hurdle'!$C$3 -> 0.0135 | F5: ='Q5c Lower carry'!$C$3 -> 0.0135
A6: Carried interest (GP share of profit) | B6: ='Q3 Base case'!$F$4 -> 0.2 | C6: ='Q4 Fee cut'!$F$4 -> 0.2 | D6: ='Q5a Hard hurdle'!$F$4 -> 0.2 | E6: ='Q5b Soft hurdle'!$F$4 -> 0.2 | F6: ='Q5c Lower carry'!$F$4 -> 0.15
A7: Hurdle rate | B7: ='Q3 Base case'!$I$2 -> 0 | C7: ='Q4 Fee cut'!$I$2 -> 0 | D7: ='Q5a Hard hurdle'!$I$2 -> 0.08 | E7: ='Q5b Soft hurdle'!$I$2 -> 0.08 | F7: ='Q5c Lower carry'!$I$2 -> 0
A8: GP catch-up | B8: =IF('Q3 Base case'!$I$2=0,"n/a",IF('Q3 Base case'!$I$3=1,"Yes","No")) -> n/a | C8: =IF('Q4 Fee cut'!$I$2=0,"n/a",IF('Q4 Fee cut'!$I$3=1,"Yes","No")) -> n/a | D8: =IF('Q5a Hard hurdle'!$I$2=0,"n/a",IF('Q5a Hard hurdle'!$I$3=1,"Yes","No")) -> No | E8: =IF('Q5b Soft hurdle'!$I$2=0,"n/a",IF('Q5b Soft hurdle'!$I$3=1,"Yes","No")) -> Yes | F8: =IF('Q5c Lower carry'!$I$2=0,"n/a",IF('Q5c Lower carry'!$I$3=1,"Yes","No")) -> n/a
A10: Limited partners (whole fund)
A11: LP net IRR | B11: ='Q3 Base case'!$C$50 -> 0.15722559 | C11: ='Q4 Fee cut'!$C$50 -> 0.15936141 | D11: ='Q5a Hard hurdle'!$C$50 -> 0.16591822 | E11: ='Q5b Soft hurdle'!$C$50 -> 0.16029224 | F11: ='Q5c Lower carry'!$C$50 -> 0.16491098
A12: Change vs current terms | B12: =('Q3 Base case'!$C$50-$B$11)*10000 -> 0 | C12: =('Q4 Fee cut'!$C$50-$B$11)*10000 -> 21.358143 | D12: =('Q5a Hard hurdle'!$C$50-$B$11)*10000 -> 86.926301 | E12: =('Q5b Soft hurdle'!$C$50-$B$11)*10000 -> 30.666435 | F12: =('Q5c Lower carry'!$C$50-$B$11)*10000 -> 76.853883
A13: LP NPV at 15% ($m) | B13: ='Q3 Base case'!$C$51 -> 578.21714 | C13: ='Q4 Fee cut'!$C$51 -> 752.97923 | D13: ='Q5a Hard hurdle'!$C$51 -> 1303.5385 | E13: ='Q5b Soft hurdle'!$C$51 -> 825.66274 | F13: ='Q5c Lower carry'!$C$51 -> 1224.1241
A14: Change vs current terms ($m) | B14: ='Q3 Base case'!$C$51-$B$13 -> 0 | C14: ='Q4 Fee cut'!$C$51-$B$13 -> 174.76209 | D14: ='Q5a Hard hurdle'!$C$51-$B$13 -> 725.32133 | E14: ='Q5b Soft hurdle'!$C$51-$B$13 -> 247.4456 | F14: ='Q5c Lower carry'!$C$51-$B$13 -> 645.90701
A15: LP distributions, nominal ($m) | B15: ='Q3 Base case'!$C$53 -> 48070.521 | C15: ='Q4 Fee cut'!$C$53 -> 48631.388 | D15: ='Q5a Hard hurdle'!$C$53 -> 50426.835 | E15: ='Q5b Soft hurdle'!$C$53 -> 48631.388 | F15: ='Q5c Lower carry'!$C$53 -> 50420.85
A16: LP multiple of contributed capital (TVPI) | B16: ='Q3 Base case'!$C$54 -> 2.403526 | C16: ='Q4 Fee cut'!$C$54 -> 2.4315694 | D16: ='Q5a Hard hurdle'!$C$54 -> 2.5213418 | E16: ='Q5b Soft hurdle'!$C$54 -> 2.4315694 | F16: ='Q5c Lower carry'!$C$54 -> 2.5210425
A18: General partner — TPG
A19: Management fees, nominal ($m) | B19: ='Q3 Base case'!$C$55 -> 3000 | C19: ='Q4 Fee cut'!$C$55 -> 2700 | D19: ='Q5a Hard hurdle'!$C$55 -> 2700 | E19: ='Q5b Soft hurdle'!$C$55 -> 2700 | F19: ='Q5c Lower carry'!$C$55 -> 2700
A20: Carried interest, nominal ($m) | B20: ='Q3 Base case'!$C$56 -> 7017.6302 | C20: ='Q4 Fee cut'!$C$56 -> 7157.847 | D20: ='Q5a Hard hurdle'!$C$56 -> 5362.4 | E20: ='Q5b Soft hurdle'!$C$56 -> 7157.847 | F20: ='Q5c Lower carry'!$C$56 -> 5368.3853
A21: PV of management fees ($m) | B21: ='Q3 Base case'!$C$57 -> 1731.4752 | C21: ='Q4 Fee cut'!$C$57 -> 1558.3277 | D21: ='Q5a Hard hurdle'!$C$57 -> 1558.3277 | E21: ='Q5b Soft hurdle'!$C$57 -> 1558.3277 | F21: ='Q5c Lower carry'!$C$57 -> 1558.3277
A22: PV of carried interest ($m) | B22: ='Q3 Base case'!$C$58 -> 1845.4937 | C22: ='Q4 Fee cut'!$C$58 -> 1884.5797 | D22: ='Q5a Hard hurdle'!$C$58 -> 1334.0204 | E22: ='Q5b Soft hurdle'!$C$58 -> 1811.8962 | F22: ='Q5c Lower carry'!$C$58 -> 1413.4348
A23: PV of total GP compensation ($m) | B23: ='Q3 Base case'!$C$59 -> 3576.9689 | C23: ='Q4 Fee cut'!$C$59 -> 3442.9073 | D23: ='Q5a Hard hurdle'!$C$59 -> 2892.3481 | E23: ='Q5b Soft hurdle'!$C$59 -> 3370.2238 | F23: ='Q5c Lower carry'!$C$59 -> 2971.7624
A24: Change vs current terms ($m) | B24: ='Q3 Base case'!$C$59-$B$23 -> 0 | C24: ='Q4 Fee cut'!$C$59-$B$23 -> -134.06158 | D24: ='Q5a Hard hurdle'!$C$59-$B$23 -> -684.62082 | E24: ='Q5b Soft hurdle'!$C$59-$B$23 -> -206.74509 | F24: ='Q5c Lower carry'!$C$59-$B$23 -> -605.2065
A25: Fees as % of GP compensation (PV) | B25: ='Q3 Base case'!$C$60 -> 0.48406213 | C25: ='Q4 Fee cut'!$C$60 -> 0.45261969 | D25: ='Q5a Hard hurdle'!$C$60 -> 0.53877597 | E25: ='Q5b Soft hurdle'!$C$60 -> 0.46238106 | F25: ='Q5c Lower carry'!$C$60 -> 0.52437828
A26: First year GP receives carry | B26: ='Q3 Base case'!$C$62 -> 8 | C26: ='Q4 Fee cut'!$C$62 -> 8 | D26: ='Q5a Hard hurdle'!$C$62 -> 9 | E26: ='Q5b Soft hurdle'!$C$62 -> 9 | F26: ='Q5c Lower carry'!$C$62 -> 8
A28: ="OPERF ($"&TEXT(Inputs!$C$26,"#,##0")&"m commitment = "&TEXT('Q3 Base case'!$C$63,"0.00%")&" of the fund)" -> OPERF ($750m commitment = 3.75% of the fund)
A29: OPERF NPV at 15% ($m) | B29: ='Q3 Base case'!$C$64 -> 21.683143 | C29: ='Q4 Fee cut'!$C$64 -> 28.236721 | D29: ='Q5a Hard hurdle'!$C$64 -> 48.882693 | E29: ='Q5b Soft hurdle'!$C$64 -> 30.962353 | F29: ='Q5c Lower carry'!$C$64 -> 45.904656
A30: Change vs current terms ($m) | B30: ='Q3 Base case'!$C$64-$B$29 -> 0 | C30: ='Q4 Fee cut'!$C$64-$B$29 -> 6.5535783 | D30: ='Q5a Hard hurdle'!$C$64-$B$29 -> 27.19955 | E30: ='Q5b Soft hurdle'!$C$64-$B$29 -> 9.2792099 | F30: ='Q5c Lower carry'!$C$64-$B$29 -> 24.221513
A31: OPERF management fees paid, nominal ($m) | B31: ='Q3 Base case'!$C$65 -> 112.5 | C31: ='Q4 Fee cut'!$C$65 -> 101.25 | D31: ='Q5a Hard hurdle'!$C$65 -> 101.25 | E31: ='Q5b Soft hurdle'!$C$65 -> 101.25 | F31: ='Q5c Lower carry'!$C$65 -> 101.25
A32: OPERF distributions received, nominal ($m) | B32: ='Q3 Base case'!$C$66 -> 1802.6445 | C32: ='Q4 Fee cut'!$C$66 -> 1823.6771 | D32: ='Q5a Hard hurdle'!$C$66 -> 1891.0063 | E32: ='Q5b Soft hurdle'!$C$66 -> 1823.6771 | F32: ='Q5c Lower carry'!$C$66 -> 1890.7819
A34: Model integrity
A35: Scenario-sheet checks | B35: ='Q3 Base case'!$C$72 -> OK | C35: ='Q4 Fee cut'!$C$72 -> OK | D35: ='Q5a Hard hurdle'!$C$72 -> OK | E35: ='Q5b Soft hurdle'!$C$72 -> OK | F35: ='Q5c Lower carry'!$C$72 -> OK
A36: Difference vs Engine rows M1–M5 (0 = reconciles) | B36: =ROUND(ABS('Q3 Base case'!$C$50-Engine!$K$7)+ABS('Q3 Base case'!$C$51-Engine!$L$7)+ABS('Q3 Base case'!$C$59-Engine!$S$7),6) -> 0 | C36: =ROUND(ABS('Q4 Fee cut'!$C$50-Engine!$K$8)+ABS('Q4 Fee cut'!$C$51-Engine!$L$8)+ABS('Q4 Fee cut'!$C$59-Engine!$S$8),6) -> 0 | D36: =ROUND(ABS('Q5a Hard hurdle'!$C$50-Engine!$K$9)+ABS('Q5a Hard hurdle'!$C$51-Engine!$L$9)+ABS('Q5a Hard hurdle'!$C$59-Engine!$S$9),6) -> 0 | E36: =ROUND(ABS('Q5b Soft hurdle'!$C$50-Engine!$K$10)+ABS('Q5b Soft hurdle'!$C$51-Engine!$L$10)+ABS('Q5b Soft hurdle'!$C$59-Engine!$S$10),6) -> 0 | F36: =ROUND(ABS('Q5c Lower carry'!$C$50-Engine!$K$11)+ABS('Q5c Lower carry'!$C$51-Engine!$L$11)+ABS('Q5c Lower carry'!$C$59-Engine!$S$11),6) -> 0
A38: Talking points (text updates with the model)
A39: ="Base case: assets grow "&TEXT(Inputs!$C$8,"0%")&" a year but LPs net "&TEXT(B11,"0.0%")&" after fees and carry; NPV at 15% is only $"&TEXT(B13,"#,##0")&"m on a $"&TEXT(Inputs!$C$6,"#,##0")&"m fund." -> Base case: assets grow 20% a year but LPs net 15.7% after fees and carry; NPV at 15% is only $578m on a $20,000m fund.
A40: ="TPG earns $"&TEXT(B23,"#,##0")&"m in PV terms; "&TEXT(B25,"0%")&" of that is management fees, which are paid whatever the fund returns." -> TPG earns $3,577m in PV terms; 48% of that is management fees, which are paid whatever the fund returns.
A41: ="TPG's fee cut adds "&TEXT(C12,"0")&" bps to LP IRR (+$"&TEXT(C30,"0.0")&"m NPV for OPERF), a small gain, as Schmitz expected." -> TPG's fee cut adds 21 bps to LP IRR (+$6.6m NPV for OPERF), a small gain, as Schmitz expected.
A42: ="On top of the offer, an 8% hard hurdle adds "&TEXT(D12-C12,"0")&" bps and a 15% carry adds "&TEXT(F12-C12,"0")&" bps; a soft hurdle (with catch-up) adds only "&TEXT(E12-C12,"0")&" bps at 20% growth." -> On top of the offer, an 8% hard hurdle adds 66 bps and a 15% carry adds 55 bps; a soft hurdle (with catch-up) adds only 9 bps at 20% growth.

Sheet Q1-Q2 Context
A1: Q1–Q2 — WHY IS TPG OFFERING THIS, AND WHAT DO FEES AND CARRY DO?
A2: Case facts for Parts 2–3 (blue = case data with source; black = calculation; green = linked to the model). $ millions unless stated.
A4: A. What TPG's December 2008 offer costs TPG (per year unless stated)
A5: TPG VI committed capital, final close Sept 2008 | C5: 19800 | D5: Case p.1; Exhibit 1
A6: Management fee — current | C6: =Inputs!$C$18 -> 0.015
A7: Management fee — offered | C7: =Inputs!$C$19 -> 0.0135
A8: Annual fee at current rate | C8: =C5*C6 -> 297
A9: Annual fee at offered rate (nobody cuts) | C9: =C5*C7 -> 267.3
A10: Cost of the fee cut to TPG per year | C10: =C8-C9 -> 29.7
A11: Cost of the fee cut over the fund life | C11: =C10*Inputs!$C$7 -> 297
A12: Fund size if every LP takes the 10% cut | C12: =C5*(1-Inputs!$C$27) -> 17820
A13: Annual fee at offered rate on the smaller fund | C13: =C12*C7 -> 240.57
A14: Maximum annual fee reduction (fee cut + full take-up) | C14: =C8-C13 -> 56.43
A15: TPG firm-wide commitments under management ($m) | C15: 50000 | D15: Case p.2 ("approximately $50.0 billion")
A16: Illustrative firm-wide fee base at the current rate | C16: =C15*C6 -> 750 | D16: Assumes 1.50% on all funds — illustration only
A17: Maximum reduction as % of the illustrative firm-wide fee base | C17: =IF(C16=0,0,C14/C16) -> 0.07524
A18: Maximum 2009 capital calls fund-wide (30% cap) | C18: =C5*Inputs!$C$31 -> 5940 | D18: Case p.1 — without advisory committee approval
A19: Reading: the offer is cheap for TPG — a few percent of firm-wide fees — which supports the "goodwill / PR" reading; the 10% cut is small next to Permira's 60%.
A21: B. U.S. private equity fundraising (Exhibit 4)
A22: Year | B22: Amount raised ($bn) | C22: Funds closed | D22: Avg fund size ($bn) | E22: Change in amount | F22: Change in funds
A23: 2004 | B23: 90 | C23: 123 | D23: =IF(C23=0,0,B23/C23) -> 0.73170732
A24: 2005 | B24: 153 | C24: 211 | D24: =IF(C24=0,0,B24/C24) -> 0.72511848 | E24: =IF(B23=0,0,B24/B23-1) -> 0.7 | F24: =IF(C23=0,0,C24/C23-1) -> 0.71544715
A25: 2006 | B25: 201 | C25: 188 | D25: =IF(C25=0,0,B25/C25) -> 1.0691489 | E25: =IF(B24=0,0,B25/B24-1) -> 0.31372549 | F25: =IF(C24=0,0,C25/C24-1) -> -0.10900474
A26: 2007 | B26: 300 | C26: 233 | D26: =IF(C26=0,0,B26/C26) -> 1.2875536 | E26: =IF(B25=0,0,B26/B25-1) -> 0.49253731 | F26: =IF(C25=0,0,C26/C25-1) -> 0.2393617
A27: 2008 | B27: 314 | C27: 187 | D27: =IF(C27=0,0,B27/C27) -> 1.6791444 | E27: =IF(B26=0,0,B27/B26-1) -> 0.046666667 | F27: =IF(C26=0,0,C27/C26-1) -> -0.19742489
A28: Source: Exhibit 4 (PitchBook). 2008 dollars were a record — funds like TPG VI closed before Lehman — but fund count fell 20% and the case says future fundraising prospects were poor (p.5).
A30: C. Exit markets and TPG VI setbacks (case p.1, p.5; Exhibit 8)
A31: U.S. IPO proceeds, 2007 ($bn, read from Exhibit 8 chart, approx.) | C31: 81 | D31: Exhibit 8
A32: U.S. IPO proceeds, 2008 ($bn, approx.) | C32: 11 | D32: Exhibit 8
A33: Number of U.S. IPOs, 2007 (approx.) | C33: 330 | D33: Exhibit 8
A34: Number of U.S. IPOs, 2008 (approx.) | C34: 50 | D34: Exhibit 8
A35: TPG IPO exits 2006: proceeds ($m) from six IPOs | C35: 3100 | D35: Case p.5
A36: TPG IPO exits 2008: proceeds ($m) from one IPO | C36: 83 | D36: Case p.5
A37: TPG investment in Washington Mutual across funds ($m) | C37: 1350 | D37: Case p.1
A38: TPG VI's share of the WaMu investment, written off ($m) | C38: 437 | D38: Case p.5
A39: WaMu loss as % of TPG VI committed capital | C39: =C38/C5 -> 0.022070707
A40: TPG VI write-down reported March 2009 | C40: 0.29 | D40: Case fn 11 (Reuters)
A41: Permira's offer to LPs: commitment cut | C41: 0.6 | D41: Case p.1
A42: TPG's offer: commitment cut | C42: =Inputs!$C$27 -> 0.1 | D42: Case p.1
A43: IPO proceeds change 2007→2008 | C43: =IF(C31=0,0,C32/C31-1) -> -0.86419753
...

Sheet Q3 Base case
A1: OREGON PUBLIC EMPLOYEES RETIREMENT FUND
B2: Committed capital ($ millions) | C2: =Inputs!$C$6 -> 20000 | E2: Asset growth rate (%) | F2: =Inputs!$C$8 -> 0.2 | H2: Hurdle rate (%) | I2: 0
B3: Management fee (%) | C3: =Inputs!$C$18 -> 0.015 | E3: Discount rate (%) | F3: =Inputs!$C$9 -> 0.15 | H3: GP catch-up (1 = yes) | I3: 0
B4: LP share of profit (%) | C4: =1-F4 -> 0.8 | E4: GP share of profit (%) | F4: =Inputs!$C$20 -> 0.2 | H4: OPERF ($ millions) | I4: =Inputs!$C$26 -> 750
A6: ="Scenario: "&"Current LPA terms — "&TEXT(C3,"0.00%")&" fee on committed capital, "&TEXT(F4,"0%")&" carry, "&IF(I2=0,"no hurdle",TEXT(I2,"0%")&" hurdle"&IF(I3=1," with 100% GP catch-up (soft)"," with no catch-up (hard)")) -> Scenario: Current LPA terms — 1.50% fee on committed capital, 20% carry, no hurdle | J6: Prep Q3 — base case
A8: Year | B8: 0 | C8: 1 | D8: 2 | E8: 3 | F8: 4 | G8: 5 | H8: 6 | I8: 7 | J8: 8 | K8: 9 | L8: 10
A9: Assumptions
A10: % Drawn of committed capital | C10: =Inputs!C$13 -> 0.2 | D10: =Inputs!D$13 -> 0.2 | E10: =Inputs!E$13 -> 0.2 | F10: =Inputs!F$13 -> 0.2 | G10: =Inputs!G$13 -> 0.2 | H10: =Inputs!H$13 -> 0 | I10: =Inputs!I$13 -> 0 | J10: =Inputs!J$13 -> 0 | ... L10: =Inputs!L$13 -> 0
A11: Distribution rate | C11: =Inputs!C$14 -> 0 | D11: =Inputs!D$14 -> 0 | E11: =Inputs!E$14 -> 0 | F11: =Inputs!F$14 -> 0 | G11: =Inputs!G$14 -> 0.2 | H11: =Inputs!H$14 -> 0.2 | I11: =Inputs!I$14 -> 0.2 | J11: =Inputs!J$14 -> 0.2 | ... L11: =Inputs!L$14 -> 1
A13: At the beginning of the year
A14: Assets | C14: =B24 -> 0 | D14: =C24 -> 4440 | E14: =D24 -> 9768 | F14: =E24 -> 16161.6 | G14: =F24 -> 23833.92 | H14: =G24 -> 26432.563 | I14: =H24 -> 25087.261 | J14: =I24 -> 23795.77 | ... L14: =K24 -> 21365.702
A15: Plus: Takedown | C15: =$C$2*C10 -> 4000 | D15: =$C$2*D10 -> 4000 | E15: =$C$2*E10 -> 4000 | F15: =$C$2*F10 -> 4000 | G15: =$C$2*G10 -> 4000 | H15: =$C$2*H10 -> 0 | I15: =$C$2*I10 -> 0 | J15: =$C$2*J10 -> 0 | ... L15: =$C$2*L10 -> 0
A16: Less: Management fee | C16: =$C$2*$C$3 -> 300 | D16: =$C$2*$C$3 -> 300 | E16: =$C$2*$C$3 -> 300 | F16: =$C$2*$C$3 -> 300 | G16: =$C$2*$C$3 -> 300 | H16: =$C$2*$C$3 -> 300 | I16: =$C$2*$C$3 -> 300 | J16: =$C$2*$C$3 -> 300 | ... L16: =$C$2*$C$3 -> 300
A17: Invested capital per period | C17: =C14+C15-C16 -> 3700 | D17: =D14+D15-D16 -> 8140 | E17: =E14+E15-E16 -> 13468 | F17: =F14+F15-F16 -> 19861.6 | G17: =G14+G15-G16 -> 27533.92 | H17: =H14+H15-H16 -> 26132.563 | I17: =I14+I15-I16 -> 24787.261 | J17: =J14+J15-J16 -> 23495.77 | ... L17: =L14+L15-L16 -> 21065.702
A19: At the end of the year
A20: Plus: Asset growth over year | C20: =C17*$F$2 -> 740 | D20: =D17*$F$2 -> 1628 | E20: =E17*$F$2 -> 2693.6 | F20: =F17*$F$2 -> 3972.32 | G20: =G17*$F$2 -> 5506.784 | H20: =H17*$F$2 -> 5226.5126 | I20: =I17*$F$2 -> 4957.4521 | J20: =J17*$F$2 -> 4699.154 | ... L20: =L17*$F$2 -> 4213.1404
A21: NAV before distributions | C21: =C17+C20 -> 4440 | D21: =D17+D20 -> 9768 | E21: =E17+E20 -> 16161.6 | F21: =F17+F20 -> 23833.92 | G21: =G17+G20 -> 33040.704 | H21: =H17+H20 -> 31359.076 | I21: =I17+I20 -> 29744.713 | J21: =J17+J20 -> 28194.924 | ... L21: =L17+L20 -> 25278.842
A23: Less: Distributions | C23: =C21*C11 -> 0 | D23: =D21*D11 -> 0 | E23: =E21*E11 -> 0 | F23: =F21*F11 -> 0 | G23: =G21*G11 -> 6608.1408 | H23: =H21*H11 -> 6271.8152 | I23: =I21*I11 -> 5948.9426 | J23: =J21*J11 -> 5638.9849 | ... L23: =L21*L11 -> 25278.842
A24: NAV after distributions | C24: =C21-C23 -> 4440 | D24: =D21-D23 -> 9768 | E24: =E21-E23 -> 16161.6 | F24: =F21-F23 -> 23833.92 | G24: =G21-G23 -> 26432.563 | H24: =H21-H23 -> 25087.261 | I24: =I21-I23 -> 23795.77 | J24: =J21-J23 -> 22555.939 | ... L24: =L21-L23 -> 0
A26: Distribution waterfall (whole-fund carry: LPs made whole first)
A27: Unreturned LP capital, incl. this year's takedown | C27: =B29+C15 -> 4000 | D27: =C29+D15 -> 8000 | E27: =D29+E15 -> 12000 | F27: =E29+F15 -> 16000 | G27: =F29+G15 -> 20000 | H27: =G29+H15 -> 13391.859 | I27: =H29+I15 -> 7120.044 | J27: =I29+J15 -> 1171.1015 | ... L27: =K29+L15 -> 0
A28: Tier 1 – Return of capital to LPs | C28: =MIN(C23,C27) -> 0 | D28: =MIN(D23,D27) -> 0 | E28: =MIN(E23,E27) -> 0 | F28: =MIN(F23,F27) -> 0 | G28: =MIN(G23,G27) -> 6608.1408 | H28: =MIN(H23,H27) -> 6271.8152 | I28: =MIN(I23,I27) -> 5948.9426 | J28: =MIN(J23,J27) -> 1171.1015 | ... L28: =MIN(L23,L27) -> 0
A29: Unreturned LP capital, end of year | C29: =C27-C28 -> 4000 | D29: =D27-D28 -> 8000 | E29: =E27-E28 -> 12000 | F29: =F27-F28 -> 16000 | G29: =G27-G28 -> 13391.859 | H29: =H27-H28 -> 7120.044 | I29: =I27-I28 -> 1171.1015 | J29: =J27-J28 -> 0 | ... L29: =L27-L28 -> 0
A30: Preferred return due (hurdle accrual + unpaid) | C30: =B32+$I$2*(C27+B32) -> 0 | D30: =C32+$I$2*(D27+C32) -> 0 | E30: =D32+$I$2*(E27+D32) -> 0 | F30: =E32+$I$2*(F27+E32) -> 0 | G30: =F32+$I$2*(G27+F32) -> 0 | H30: =G32+$I$2*(H27+G32) -> 0 | I30: =H32+$I$2*(I27+H32) -> 0 | J30: =I32+$I$2*(J27+I32) -> 0 | ... L30: =K32+$I$2*(L27+K32) -> 0
A31: Tier 2 – Preferred return paid to LPs | C31: =MIN(C23-C28,C30) -> 0 | D31: =MIN(D23-D28,D30) -> 0 | E31: =MIN(E23-E28,E30) -> 0 | F31: =MIN(F23-F28,F30) -> 0 | G31: =MIN(G23-G28,G30) -> 0 | H31: =MIN(H23-H28,H30) -> 0 | I31: =MIN(I23-I28,I30) -> 0 | J31: =MIN(J23-J28,J30) -> 0 | ... L31: =MIN(L23-L28,L30) -> 0
A32: Unpaid preferred return, end of year | C32: =C30-C31 -> 0 | D32: =D30-D31 -> 0 | E32: =E30-E31 -> 0 | F32: =F30-F31 -> 0 | G32: =G30-G31 -> 0 | H32: =H30-H31 -> 0 | I32: =I30-I31 -> 0 | J32: =J30-J31 -> 0 | ... L32: =L30-L31 -> 0
A33: Tier 3 – GP catch-up (soft hurdle only) | C33: =IF($I$3=1,MIN(C23-C28-C31,MAX(0,$F$4/(1-$F$4)*(B37+C31)-B38)),0) -> 0 | D33: =IF($I$3=1,MIN(D23-D28-D31,MAX(0,$F$4/(1-$F$4)*(C37+D31)-C38)),0) -> 0 | E33: =IF($I$3=1,MIN(E23-E28-E31,MAX(0,$F$4/(1-$F$4)*(D37+E31)-D38)),0) -> 0 | F33: =IF($I$3=1,MIN(F23-F28-F31,MAX(0,$F$4/(1-$F$4)*(E37+F31)-E38)),0) -> 0 | G33: =IF($I$3=1,MIN(G23-G28-G31,MAX(0,$F$4/(1-$F$4)*(F37+G31)-F38)),0) -> 0 | H33: =IF($I$3=1,MIN(H23-H28-H31,MAX(0,$F$4/(1-$F$4)*(G37+H31)-G38)),0) -> 0 | I33: =IF($I$3=1,MIN(I23-I28-I31,MAX(0,$F$4/(1-$F$4)*(H37+I31)-H38)),0) -> 0 | J33: =IF($I$3=1,MIN(J23-J28-J31,MAX(0,$F$4/(1-$F$4)*(I37+J31)-I38)),0) -> 0 | ... L33: =IF($I$3=1,MIN(L23-L28-L31,MAX(0,$F$4/(1-$F$4)*(K37+L31)-K38)),0) -> 0
A34: Tier 4 – Remaining profit split LP/GP | C34: =C23-C28-C31-C33 -> 0 | D34: =D23-D28-D31-D33 -> 0 | E34: =E23-E28-E31-E33 -> 0 | F34: =F23-F28-F31-F33 -> 0 | G34: =G23-G28-G31-G33 -> 0 | H34: =H23-H28-H31-H33 -> 0 | I34: =I23-I28-I31-I33 -> 0 | J34: =J23-J28-J31-J33 -> 4467.8834 | ... L34: =L23-L28-L31-L33 -> 25278.842
A35: Total distributions to LPs | C35: =C28+C31+$C$4*C34 -> 0 | D35: =D28+D31+$C$4*D34 -> 0 | E35: =E28+E31+$C$4*E34 -> 0 | F35: =F28+F31+$C$4*F34 -> 0 | G35: =G28+G31+$C$4*G34 -> 6608.1408 | H35: =H28+H31+$C$4*H34 -> 6271.8152 | I35: =I28+I31+$C$4*I34 -> 5948.9426 | J35: =J28+J31+$C$4*J34 -> 4745.4082 | ... L35: =L28+L31+$C$4*L34 -> 20223.074
A36: Total carried interest to GP | C36: =C33+$F$4*C34 -> 0 | D36: =D33+$F$4*D34 -> 0 | E36: =E33+$F$4*E34 -> 0 | F36: =F33+$F$4*F34 -> 0 | G36: =G33+$F$4*G34 -> 0 | H36: =H33+$F$4*H34 -> 0 | I36: =I33+$F$4*I34 -> 0 | J36: =J33+$F$4*J34 -> 893.57668 | ... L36: =L33+$F$4*L34 -> 5055.7684
A37: Cumulative LP profit received | C37: =B37+C31+$C$4*C34 -> 0 | D37: =C37+D31+$C$4*D34 -> 0 | E37: =D37+E31+$C$4*E34 -> 0 | F37: =E37+F31+$C$4*F34 -> 0 | G37: =F37+G31+$C$4*G34 -> 0 | H37: =G37+H31+$C$4*H34 -> 0 | I37: =H37+I31+$C$4*I34 -> 0 | J37: =I37+J31+$C$4*J34 -> 3574.3067 | ... L37: =K37+L31+$C$4*L34 -> 28070.521
A38: Cumulative GP carried interest | C38: =B38+C36 -> 0 | D38: =C38+D36 -> 0 | E38: =D38+E36 -> 0 | F38: =E38+F36 -> 0 | G38: =F38+G36 -> 0 | H38: =G38+H36 -> 0 | I38: =H38+I36 -> 0 | J38: =I38+J36 -> 893.57668 | ... L38: =K38+L36 -> 7017.6302
A40: Cash flows by date (column = point in time t: the start of Year n is t = n − 1; the end of Year n is t = n)
A41: LP: capital calls (takedowns) | B41: =IF(B$8>=COLUMNS($C$15:$L$15),0,-INDEX($C$15:$L$15,B$8+1)) -> -4000 | C41: =IF(C$8>=COLUMNS($C$15:$L$15),0,-INDEX($C$15:$L$15,C$8+1)) -> -4000 | D41: =IF(D$8>=COLUMNS($C$15:$L$15),0,-INDEX($C$15:$L$15,D$8+1)) -> -4000 | E41: =IF(E$8>=COLUMNS($C$15:$L$15),0,-INDEX($C$15:$L$15,E$8+1)) -> -4000 | F41: =IF(F$8>=COLUMNS($C$15:$L$15),0,-INDEX($C$15:$L$15,F$8+1)) -> -4000 | G41: =IF(G$8>=COLUMNS($C$15:$L$15),0,-INDEX($C$15:$L$15,G$8+1)) -> 0 | H41: =IF(H$8>=COLUMNS($C$15:$L$15),0,-INDEX($C$15:$L$15,H$8+1)) -> 0 | I41: =IF(I$8>=COLUMNS($C$15:$L$15),0,-INDEX($C$15:$L$15,I$8+1)) -> 0 | ... L41: =IF(L$8>=COLUMNS($C$15:$L$15),0,-INDEX($C$15:$L$15,L$8+1)) -> 0
A42: LP: distributions received | B42: =IF(B$8=0,0,INDEX($C$35:$L$35,B$8)) -> 0 | C42: =IF(C$8=0,0,INDEX($C$35:$L$35,C$8)) -> 0 | D42: =IF(D$8=0,0,INDEX($C$35:$L$35,D$8)) -> 0 | E42: =IF(E$8=0,0,INDEX($C$35:$L$35,E$8)) -> 0 | F42: =IF(F$8=0,0,INDEX($C$35:$L$35,F$8)) -> 0 | G42: =IF(G$8=0,0,INDEX($C$35:$L$35,G$8)) -> 6608.1408 | H42: =IF(H$8=0,0,INDEX($C$35:$L$35,H$8)) -> 6271.8152 | I42: =IF(I$8=0,0,INDEX($C$35:$L$35,I$8)) -> 5948.9426 | ... L42: =IF(L$8=0,0,INDEX($C$35:$L$35,L$8)) -> 20223.074
A43: LP: net cash flow | B43: =B41+B42 -> -4000 | C43: =C41+C42 -> -4000 | D43: =D41+D42 -> -4000 | E43: =E41+E42 -> -4000 | F43: =F41+F42 -> -4000 | G43: =G41+G42 -> 6608.1408 | H43: =H41+H42 -> 6271.8152 | I43: =I41+I42 -> 5948.9426 | ... L43: =L41+L42 -> 20223.074
A44: GP: management fees received | B44: =IF(B$8>=COLUMNS($C$16:$L$16),0,INDEX($C$16:$L$16,B$8+1)) -> 300 | C44: =IF(C$8>=COLUMNS($C$16:$L$16),0,INDEX($C$16:$L$16,C$8+1)) -> 300 | D44: =IF(D$8>=COLUMNS($C$16:$L$16),0,INDEX($C$16:$L$16,D$8+1)) -> 300 | E44: =IF(E$8>=COLUMNS($C$16:$L$16),0,INDEX($C$16:$L$16,E$8+1)) -> 300 | F44: =IF(F$8>=COLUMNS($C$16:$L$16),0,INDEX($C$16:$L$16,F$8+1)) -> 300 | G44: =IF(G$8>=COLUMNS($C$16:$L$16),0,INDEX($C$16:$L$16,G$8+1)) -> 300 | H44: =IF(H$8>=COLUMNS($C$16:$L$16),0,INDEX($C$16:$L$16,H$8+1)) -> 300 | I44: =IF(I$8>=COLUMNS($C$16:$L$16),0,INDEX($C$16:$L$16,I$8+1)) -> 300 | ... L44: =IF(L$8>=COLUMNS($C$16:$L$16),0,INDEX($C$16:$L$16,L$8+1)) -> 0
A45: GP: carried interest received | B45: =IF(B$8=0,0,INDEX($C$36:$L$36,B$8)) -> 0 | C45: =IF(C$8=0,0,INDEX($C$36:$L$36,C$8)) -> 0 | D45: =IF(D$8=0,0,INDEX($C$36:$L$36,D$8)) -> 0 | E45: =IF(E$8=0,0,INDEX($C$36:$L$36,E$8)) -> 0 | F45: =IF(F$8=0,0,INDEX($C$36:$L$36,F$8)) -> 0 | G45: =IF(G$8=0,0,INDEX($C$36:$L$36,G$8)) -> 0 | H45: =IF(H$8=0,0,INDEX($C$36:$L$36,H$8)) -> 0 | I45: =IF(I$8=0,0,INDEX($C$36:$L$36,I$8)) -> 0 | ... L45: =IF(L$8=0,0,INDEX($C$36:$L$36,L$8)) -> 5055.7684
A46: GP: total compensation | B46: =B44+B45 -> 300 | C46: =C44+C45 -> 300 | D46: =D44+D45 -> 300 | E46: =E44+E45 -> 300 | F46: =F44+F45 -> 300 | G46: =G44+G45 -> 300 | H46: =H44+H45 -> 300 | I46: =I44+I45 -> 300 | ... L46: =L44+L45 -> 5055.7684
A47: OPERF: net cash flow (pro-rata share of LP) | B47: =$C$63*B43 -> -150 | C47: =$C$63*C43 -> -150 | D47: =$C$63*D43 -> -150 | E47: =$C$63*E43 -> -150 | F47: =$C$63*F43 -> -150 | G47: =$C$63*G43 -> 247.80528 | H47: =$C$63*H43 -> 235.19307 | I47: =$C$63*I43 -> 223.08535 | ... L47: =$C$63*L43 -> 758.36527
...

Sheet Q3 Analysis
A1: Q3 — FINANCIAL IMPLICATIONS OF THE GP/LP COMPENSATION STRUCTURE
A2: Base case: $20bn fund, 1.50% fee on committed capital, 20% carry, no hurdle, assets grow 20% a year, 15% discount rate (sheet "Q3 Base case").
A4: A. Base-case outcome ($ millions)
A5: LP net IRR | C5: ='Q3 Base case'!$C$50 -> 0.15722559 | D5: vs 20% gross asset growth
A6: LP NPV at 15% | C6: ='Q3 Base case'!$C$51 -> 578.21714
A7: LP multiple (TVPI) | C7: ='Q3 Base case'!$C$54 -> 2.403526
A8: GP management fees (nominal) | C8: ='Q3 Base case'!$C$55 -> 3000
A9: GP carried interest (nominal) | C9: ='Q3 Base case'!$C$56 -> 7017.6302
A10: PV of management fees | C10: ='Q3 Base case'!$C$57 -> 1731.4752
A11: PV of carried interest | C11: ='Q3 Base case'!$C$58 -> 1845.4937
A12: PV of total GP compensation | C12: ='Q3 Base case'!$C$59 -> 3576.9689
A13: Fees as % of GP compensation (PV) | C13: ='Q3 Base case'!$C$60 -> 0.48406213 | D13: fees are fixed pay — collected whether or not the fund performs
A14: First year TPG receives carry | C14: ='Q3 Base case'!$C$62 -> 8 | D14: carry only starts once LPs have their $20bn back
A16: B. Gross-to-net bridge — what fees and carry cost LPs
B17: LP IRR | C17: Drag (bps)
A18: Gross: asset return with no fees and no carry | B18: =Engine!$K$16 -> 0.2
A19: After 1.50% management fee only | B19: =Engine!$K$17 -> 0.17804892 | C19: =(B18-B19)*10000 -> 219.51075
A20: After management fee and 20% carry (LP net) | B20: ='Q3 Base case'!$C$50 -> 0.15722559 | C20: =(B19-B20)*10000 -> 208.2333
A21: Total drag | C21: =C19+C20 -> 427.74406
A23: C. Who captures the value created above the 15% required return (PV at 15%, $ millions)
B24: $ millions | C24: Share
A25: LPs: NPV of net cash flows | B25: ='Q3 Base case'!$C$51 -> 578.21714 | C25: =IF($B$28=0,0,B25/$B$28) -> 0.13915554 | D25: LPs put up all the capital and bear the risk...
A26: TPG: management fees | B26: ='Q3 Base case'!$C$57 -> 1731.4752 | C26: =IF($B$28=0,0,B26/$B$28) -> 0.4167022 | D26: ...but most of the value above 15% goes to the GP
A27: TPG: carried interest | B27: ='Q3 Base case'!$C$58 -> 1845.4937 | C27: =IF($B$28=0,0,B27/$B$28) -> 0.44414226
A28: Total value to LPs and TPG | B28: =SUM(B25:B27) -> 4155.1861 | C28: =IF($B$28=0,0,B28/$B$28) -> 1
A29: Memo: NPV of the fund with no fees and no carry | B29: =Engine!$L$16 -> 4562.1912
A30: Memo: growth lost because fees leave the invested base | B30: =B29-B28 -> 407.00511 | D30: fee dollars would have compounded at 20% inside the fund
A31: TPG's figures are before its operating costs (salaries, offices), which management fees are meant to cover (Exhibit 12).
A32: D. Fixed vs performance pay — TPG compensation across fund outcomes (current terms)
A33: Asset growth | B33: LP net IRR | C33: LP NPV | D33: PV mgmt fees | E33: PV carry | F33: PV total GP | G33: Fees % of GP
A34: =Engine!$I$21 -> 0 | B34: =Engine!$K$21 -> -0.028740632 | C34: =Engine!$L$21 -> -9275.938 | D34: =Engine!$Q$21 -> 1731.4752 | E34: =Engine!$R$21 -> 0 | F34: =D34+E34 -> 1731.4752 | G34: =IF(F34=0,0,D34/F34) -> 1
A35: =Engine!$I$26 -> 0.05 | B35: =Engine!$K$26 -> 0.019506054 | C35: =Engine!$L$26 -> -7534.8785 | D35: =Engine!$Q$26 -> 1731.4752 | E35: =Engine!$R$26 -> 143.71312 | F35: =D35+E35 -> 1875.1883 | G35: =IF(F35=0,0,D35/F35) -> 0.9233607
A36: =Engine!$I$31 -> 0.1 | B36: =Engine!$K$31 -> 0.064190788 | C36: =Engine!$L$31 -> -5465.5015 | D36: =Engine!$Q$31 -> 1731.4752 | E36: =Engine!$R$31 -> 533.26558 | F36: =D36+E36 -> 2264.7408 | G36: =IF(F36=0,0,D36/F36) -> 0.76453571
A37: =Engine!$I$36 -> 0.15 | B37: =Engine!$K$36 -> 0.1104452 | C37: =Engine!$L$36 -> -2810.4186 | D37: =Engine!$Q$36 -> 1731.4752 | E37: =Engine!$R$36 -> 1078.9434 | F37: =D37+E37 -> 2810.4186 | G37: =IF(F37=0,0,D37/F37) -> 0.61609156
A38: =Engine!$I$41 -> 0.2 | B38: =Engine!$K$41 -> 0.15722559 | C38: =Engine!$L$41 -> 578.21714 | D38: =Engine!$Q$41 -> 1731.4752 | E38: =Engine!$R$41 -> 1845.4937 | F38: =D38+E38 -> 3576.9689 | G38: =IF(F38=0,0,D38/F38) -> 0.48406213
A39: =Engine!$I$46 -> 0.25 | B39: =Engine!$K$46 -> 0.20431317 | C39: =Engine!$L$46 -> 4929.74 | D39: =Engine!$Q$46 -> 1731.4752 | E39: =Engine!$R$46 -> 2871.6653 | F39: =D39+E39 -> 4603.1405 | G39: =IF(F39=0,0,D39/F39) -> 0.37615084
A40: =Engine!$I$51 -> 0.3 | B40: =Engine!$K$51 -> 0.25164567 | C40: =Engine!$L$51 -> 10522.138 | D40: =Engine!$Q$51 -> 1731.4752 | E40: =Engine!$R$51 -> 4215.6996 | F40: =D40+E40 -> 5947.1748 | G40: =IF(F40=0,0,D40/F40) -> 0.29114247
A41: Even if the fund only returns capital (0–5% growth) and LPs lose money, TPG still collects the full fee stream.
A43: E. Fee income scales with fund size — TPG flagship buyout funds (Exhibit 1)
A44: Fund | B44: Vintage | C44: Committed ($m) | D44: Fee rate | E44: Annual fee ($m) | F44: 10-year fees ($m) | G44: × Fund I
...

Sheet Q4 Fee cut
A1: OREGON PUBLIC EMPLOYEES RETIREMENT FUND
B2: Committed capital ($ millions) | C2: =Inputs!$C$6 -> 20000 | E2: Asset growth rate (%) | F2: =Inputs!$C$8 -> 0.2 | H2: Hurdle rate (%) | I2: 0
B3: Management fee (%) | C3: =Inputs!$C$19 -> 0.0135 | E3: Discount rate (%) | F3: =Inputs!$C$9 -> 0.15 | H3: GP catch-up (1 = yes) | I3: 0
B4: LP share of profit (%) | C4: =1-F4 -> 0.8 | E4: GP share of profit (%) | F4: =Inputs!$C$20 -> 0.2 | H4: OPERF ($ millions) | I4: =Inputs!$C$26 -> 750
A6: ="Scenario: "&"TPG offer — "&TEXT(C3,"0.00%")&" fee on committed capital, "&TEXT(F4,"0%")&" carry, "&IF(I2=0,"no hurdle",TEXT(I2,"0%")&" hurdle"&IF(I3=1," with 100% GP catch-up (soft)"," with no catch-up (hard)")) -> Scenario: TPG offer — 1.35% fee on committed capital, 20% carry, no hurdle | J6: Prep Q4 — fee cut to 1.35%
A8: Year | B8: 0 | C8: 1 | D8: 2 | E8: 3 | F8: 4 | G8: 5 | H8: 6 | I8: 7 | J8: 8 | K8: 9 | L8: 10
A9: Assumptions
A10: % Drawn of committed capital | C10: =Inputs!C$13 -> 0.2 | D10: =Inputs!D$13 -> 0.2 | E10: =Inputs!E$13 -> 0.2 | F10: =Inputs!F$13 -> 0.2 | G10: =Inputs!G$13 -> 0.2 | H10: =Inputs!H$13 -> 0 | I10: =Inputs!I$13 -> 0 | J10: =Inputs!J$13 -> 0 | ... L10: =Inputs!L$13 -> 0
A11: Distribution rate | C11: =Inputs!C$14 -> 0 | D11: =Inputs!D$14 -> 0 | E11: =Inputs!E$14 -> 0 | F11: =Inputs!F$14 -> 0 | G11: =Inputs!G$14 -> 0.2 | H11: =Inputs!H$14 -> 0.2 | I11: =Inputs!I$14 -> 0.2 | J11: =Inputs!J$14 -> 0.2 | ... L11: =Inputs!L$14 -> 1
A13: At the beginning of the year
A14: Assets | C14: =B24 -> 0 | D14: =C24 -> 4476 | E14: =D24 -> 9847.2 | F14: =E24 -> 16292.64 | G14: =F24 -> 24027.168 | H14: =G24 -> 26646.881 | I14: =H24 -> 25321.806 | J14: =I24 -> 24049.734 | ... L14: =K24 -> 21656.203
A15: Plus: Takedown | C15: =$C$2*C10 -> 4000 | D15: =$C$2*D10 -> 4000 | E15: =$C$2*E10 -> 4000 | F15: =$C$2*F10 -> 4000 | G15: =$C$2*G10 -> 4000 | H15: =$C$2*H10 -> 0 | I15: =$C$2*I10 -> 0 | J15: =$C$2*J10 -> 0 | ... L15: =$C$2*L10 -> 0
A16: Less: Management fee | C16: =$C$2*$C$3 -> 270 | D16: =$C$2*$C$3 -> 270 | E16: =$C$2*$C$3 -> 270 | F16: =$C$2*$C$3 -> 270 | G16: =$C$2*$C$3 -> 270 | H16: =$C$2*$C$3 -> 270 | I16: =$C$2*$C$3 -> 270 | J16: =$C$2*$C$3 -> 270 | ... L16: =$C$2*$C$3 -> 270
A17: Invested capital per period | C17: =C14+C15-C16 -> 3730 | D17: =D14+D15-D16 -> 8206 | E17: =E14+E15-E16 -> 13577.2 | F17: =F14+F15-F16 -> 20022.64 | G17: =G14+G15-G16 -> 27757.168 | H17: =H14+H15-H16 -> 26376.881 | I17: =I14+I15-I16 -> 25051.806 | J17: =J14+J15-J16 -> 23779.734 | ... L17: =L14+L15-L16 -> 21386.203
A19: At the end of the year
A20: Plus: Asset growth over year | C20: =C17*$F$2 -> 746 | D20: =D17*$F$2 -> 1641.2 | E20: =E17*$F$2 -> 2715.44 | F20: =F17*$F$2 -> 4004.528 | G20: =G17*$F$2 -> 5551.4336 | H20: =H17*$F$2 -> 5275.3763 | I20: =I17*$F$2 -> 5010.3612 | J20: =J17*$F$2 -> 4755.9468 | ... L20: =L17*$F$2 -> 4277.2405
A21: NAV before distributions | C21: =C17+C20 -> 4476 | D21: =D17+D20 -> 9847.2 | E21: =E17+E20 -> 16292.64 | F21: =F17+F20 -> 24027.168 | G21: =G17+G20 -> 33308.602 | H21: =H17+H20 -> 31652.258 | I21: =I17+I20 -> 30062.167 | J21: =J17+J20 -> 28535.681 | ... L21: =L17+L20 -> 25663.443
A23: Less: Distributions | C23: =C21*C11 -> 0 | D23: =D21*D11 -> 0 | E23: =E21*E11 -> 0 | F23: =F21*F11 -> 0 | G23: =G21*G11 -> 6661.7203 | H23: =H21*H11 -> 6330.4515 | I23: =I21*I11 -> 6012.4334 | J23: =J21*J11 -> 5707.1361 | ... L23: =L21*L11 -> 25663.443
A24: NAV after distributions | C24: =C21-C23 -> 4476 | D24: =D21-D23 -> 9847.2 | E24: =E21-E23 -> 16292.64 | F24: =F21-F23 -> 24027.168 | G24: =G21-G23 -> 26646.881 | H24: =H21-H23 -> 25321.806 | I24: =I21-I23 -> 24049.734 | J24: =J21-J23 -> 22828.544 | ... L24: =L21-L23 -> 0
A26: Distribution waterfall (whole-fund carry: LPs made whole first)
A27: Unreturned LP capital, incl. this year's takedown | C27: =B29+C15 -> 4000 | D27: =C29+D15 -> 8000 | E27: =D29+E15 -> 12000 | F27: =E29+F15 -> 16000 | G27: =F29+G15 -> 20000 | H27: =G29+H15 -> 13338.28 | I27: =H29+I15 -> 7007.8282 | J27: =I29+J15 -> 995.39473 | ... L27: =K29+L15 -> 0
A28: Tier 1 – Return of capital to LPs | C28: =MIN(C23,C27) -> 0 | D28: =MIN(D23,D27) -> 0 | E28: =MIN(E23,E27) -> 0 | F28: =MIN(F23,F27) -> 0 | G28: =MIN(G23,G27) -> 6661.7203 | H28: =MIN(H23,H27) -> 6330.4515 | I28: =MIN(I23,I27) -> 6012.4334 | J28: =MIN(J23,J27) -> 995.39473 | ... L28: =MIN(L23,L27) -> 0
A29: Unreturned LP capital, end of year | C29: =C27-C28 -> 4000 | D29: =D27-D28 -> 8000 | E29: =E27-E28 -> 12000 | F29: =F27-F28 -> 16000 | G29: =G27-G28 -> 13338.28 | H29: =H27-H28 -> 7007.8282 | I29: =I27-I28 -> 995.39473 | J29: =J27-J28 -> 0 | ... L29: =L27-L28 -> 0
A30: Preferred return due (hurdle accrual + unpaid) | C30: =B32+$I$2*(C27+B32) -> 0 | D30: =C32+$I$2*(D27+C32) -> 0 | E30: =D32+$I$2*(E27+D32) -> 0 | F30: =E32+$I$2*(F27+E32) -> 0 | G30: =F32+$I$2*(G27+F32) -> 0 | H30: =G32+$I$2*(H27+G32) -> 0 | I30: =H32+$I$2*(I27+H32) -> 0 | J30: =I32+$I$2*(J27+I32) -> 0 | ... L30: =K32+$I$2*(L27+K32) -> 0
A31: Tier 2 – Preferred return paid to LPs | C31: =MIN(C23-C28,C30) -> 0 | D31: =MIN(D23-D28,D30) -> 0 | E31: =MIN(E23-E28,E30) -> 0 | F31: =MIN(F23-F28,F30) -> 0 | G31: =MIN(G23-G28,G30) -> 0 | H31: =MIN(H23-H28,H30) -> 0 | I31: =MIN(I23-I28,I30) -> 0 | J31: =MIN(J23-J28,J30) -> 0 | ... L31: =MIN(L23-L28,L30) -> 0
A32: Unpaid preferred return, end of year | C32: =C30-C31 -> 0 | D32: =D30-D31 -> 0 | E32: =E30-E31 -> 0 | F32: =F30-F31 -> 0 | G32: =G30-G31 -> 0 | H32: =H30-H31 -> 0 | I32: =I30-I31 -> 0 | J32: =J30-J31 -> 0 | ... L32: =L30-L31 -> 0
A33: Tier 3 – GP catch-up (soft hurdle only) | C33: =IF($I$3=1,MIN(C23-C28-C31,MAX(0,$F$4/(1-$F$4)*(B37+C31)-B38)),0) -> 0 | D33: =IF($I$3=1,MIN(D23-D28-D31,MAX(0,$F$4/(1-$F$4)*(C37+D31)-C38)),0) -> 0 | E33: =IF($I$3=1,MIN(E23-E28-E31,MAX(0,$F$4/(1-$F$4)*(D37+E31)-D38)),0) -> 0 | F33: =IF($I$3=1,MIN(F23-F28-F31,MAX(0,$F$4/(1-$F$4)*(E37+F31)-E38)),0) -> 0 | G33: =IF($I$3=1,MIN(G23-G28-G31,MAX(0,$F$4/(1-$F$4)*(F37+G31)-F38)),0) -> 0 | H33: =IF($I$3=1,MIN(H23-H28-H31,MAX(0,$F$4/(1-$F$4)*(G37+H31)-G38)),0) -> 0 | I33: =IF($I$3=1,MIN(I23-I28-I31,MAX(0,$F$4/(1-$F$4)*(H37+I31)-H38)),0) -> 0 | J33: =IF($I$3=1,MIN(J23-J28-J31,MAX(0,$F$4/(1-$F$4)*(I37+J31)-I38)),0) -> 0 | ... L33: =IF($I$3=1,MIN(L23-L28-L31,MAX(0,$F$4/(1-$F$4)*(K37+L31)-K38)),0) -> 0
A34: Tier 4 – Remaining profit split LP/GP | C34: =C23-C28-C31-C33 -> 0 | D34: =D23-D28-D31-D33 -> 0 | E34: =E23-E28-E31-E33 -> 0 | F34: =F23-F28-F31-F33 -> 0 | G34: =G23-G28-G31-G33 -> 0 | H34: =H23-H28-H31-H33 -> 0 | I34: =I23-I28-I31-I33 -> 0 | J34: =J23-J28-J31-J33 -> 4711.7414 | ... L34: =L23-L28-L31-L33 -> 25663.443
A35: Total distributions to LPs | C35: =C28+C31+$C$4*C34 -> 0 | D35: =D28+D31+$C$4*D34 -> 0 | E35: =E28+E31+$C$4*E34 -> 0 | F35: =F28+F31+$C$4*F34 -> 0 | G35: =G28+G31+$C$4*G34 -> 6661.7203 | H35: =H28+H31+$C$4*H34 -> 6330.4515 | I35: =I28+I31+$C$4*I34 -> 6012.4334 | J35: =J28+J31+$C$4*J34 -> 4764.7878 | ... L35: =L28+L31+$C$4*L34 -> 20530.755
A36: Total carried interest to GP | C36: =C33+$F$4*C34 -> 0 | D36: =D33+$F$4*D34 -> 0 | E36: =E33+$F$4*E34 -> 0 | F36: =F33+$F$4*F34 -> 0 | G36: =G33+$F$4*G34 -> 0 | H36: =H33+$F$4*H34 -> 0 | I36: =I33+$F$4*I34 -> 0 | J36: =J33+$F$4*J34 -> 942.34828 | ... L36: =L33+$F$4*L34 -> 5132.6886
A37: Cumulative LP profit received | C37: =B37+C31+$C$4*C34 -> 0 | D37: =C37+D31+$C$4*D34 -> 0 | E37: =D37+E31+$C$4*E34 -> 0 | F37: =E37+F31+$C$4*F34 -> 0 | G37: =F37+G31+$C$4*G34 -> 0 | H37: =G37+H31+$C$4*H34 -> 0 | I37: =H37+I31+$C$4*I34 -> 0 | J37: =I37+J31+$C$4*J34 -> 3769.3931 | ... L37: =K37+L31+$C$4*L34 -> 28631.388
A38: Cumulative GP carried interest | C38: =B38+C36 -> 0 | D38: =C38+D36 -> 0 | E38: =D38+E36 -> 0 | F38: =E38+F36 -> 0 | G38: =F38+G36 -> 0 | H38: =G38+H36 -> 0 | I38: =H38+I36 -> 0 | J38: =I38+J36 -> 942.34828 | ... L38: =K38+L36 -> 7157.847
A40: Cash flows by date (column = point in time t: the start of Year n is t = n − 1; the end of Year n is t = n)
A41: LP: capital calls (takedowns) | B41: =IF(B$8>=COLUMNS($C$15:$L$15),0,-INDEX($C$15:$L$15,B$8+1)) -> -4000 | C41: =IF(C$8>=COLUMNS($C$15:$L$15),0,-INDEX($C$15:$L$15,C$8+1)) -> -4000 | D41: =IF(D$8>=COLUMNS($C$15:$L$15),0,-INDEX($C$15:$L$15,D$8+1)) -> -4000 | E41: =IF(E$8>=COLUMNS($C$15:$L$15),0,-INDEX($C$15:$L$15,E$8+1)) -> -4000 | F41: =IF(F$8>=COLUMNS($C$15:$L$15),0,-INDEX($C$15:$L$15,F$8+1)) -> -4000 | G41: =IF(G$8>=COLUMNS($C$15:$L$15),0,-INDEX($C$15:$L$15,G$8+1)) -> 0 | H41: =IF(H$8>=COLUMNS($C$15:$L$15),0,-INDEX($C$15:$L$15,H$8+1)) -> 0 | I41: =IF(I$8>=COLUMNS($C$15:$L$15),0,-INDEX($C$15:$L$15,I$8+1)) -> 0 | ... L41: =IF(L$8>=COLUMNS($C$15:$L$15),0,-INDEX($C$15:$L$15,L$8+1)) -> 0
A42: LP: distributions received | B42: =IF(B$8=0,0,INDEX($C$35:$L$35,B$8)) -> 0 | C42: =IF(C$8=0,0,INDEX($C$35:$L$35,C$8)) -> 0 | D42: =IF(D$8=0,0,INDEX($C$35:$L$35,D$8)) -> 0 | E42: =IF(E$8=0,0,INDEX($C$35:$L$35,E$8)) -> 0 | F42: =IF(F$8=0,0,INDEX($C$35:$L$35,F$8)) -> 0 | G42: =IF(G$8=0,0,INDEX($C$35:$L$35,G$8)) -> 6661.7203 | H42: =IF(H$8=0,0,INDEX($C$35:$L$35,H$8)) -> 6330.4515 | I42: =IF(I$8=0,0,INDEX($C$35:$L$35,I$8)) -> 6012.4334 | ... L42: =IF(L$8=0,0,INDEX($C$35:$L$35,L$8)) -> 20530.755
A43: LP: net cash flow | B43: =B41+B42 -> -4000 | C43: =C41+C42 -> -4000 | D43: =D41+D42 -> -4000 | E43: =E41+E42 -> -4000 | F43: =F41+F42 -> -4000 | G43: =G41+G42 -> 6661.7203 | H43: =H41+H42 -> 6330.4515 | I43: =I41+I42 -> 6012.4334 | ... L43: =L41+L42 -> 20530.755
A44: GP: management fees received | B44: =IF(B$8>=COLUMNS($C$16:$L$16),0,INDEX($C$16:$L$16,B$8+1)) -> 270 | C44: =IF(C$8>=COLUMNS($C$16:$L$16),0,INDEX($C$16:$L$16,C$8+1)) -> 270 | D44: =IF(D$8>=COLUMNS($C$16:$L$16),0,INDEX($C$16:$L$16,D$8+1)) -> 270 | E44: =IF(E$8>=COLUMNS($C$16:$L$16),0,INDEX($C$16:$L$16,E$8+1)) -> 270 | F44: =IF(F$8>=COLUMNS($C$16:$L$16),0,INDEX($C$16:$L$16,F$8+1)) -> 270 | G44: =IF(G$8>=COLUMNS($C$16:$L$16),0,INDEX($C$16:$L$16,G$8+1)) -> 270 | H44: =IF(H$8>=COLUMNS($C$16:$L$16),0,INDEX($C$16:$L$16,H$8+1)) -> 270 | I44: =IF(I$8>=COLUMNS($C$16:$L$16),0,INDEX($C$16:$L$16,I$8+1)) -> 270 | ... L44: =IF(L$8>=COLUMNS($C$16:$L$16),0,INDEX($C$16:$L$16,L$8+1)) -> 0
A45: GP: carried interest received | B45: =IF(B$8=0,0,INDEX($C$36:$L$36,B$8)) -> 0 | C45: =IF(C$8=0,0,INDEX($C$36:$L$36,C$8)) -> 0 | D45: =IF(D$8=0,0,INDEX($C$36:$L$36,D$8)) -> 0 | E45: =IF(E$8=0,0,INDEX($C$36:$L$36,E$8)) -> 0 | F45: =IF(F$8=0,0,INDEX($C$36:$L$36,F$8)) -> 0 | G45: =IF(G$8=0,0,INDEX($C$36:$L$36,G$8)) -> 0 | H45: =IF(H$8=0,0,INDEX($C$36:$L$36,H$8)) -> 0 | I45: =IF(I$8=0,0,INDEX($C$36:$L$36,I$8)) -> 0 | ... L45: =IF(L$8=0,0,INDEX($C$36:$L$36,L$8)) -> 5132.6886
A46: GP: total compensation | B46: =B44+B45 -> 270 | C46: =C44+C45 -> 270 | D46: =D44+D45 -> 270 | E46: =E44+E45 -> 270 | F46: =F44+F45 -> 270 | G46: =G44+G45 -> 270 | H46: =H44+H45 -> 270 | I46: =I44+I45 -> 270 | ... L46: =L44+L45 -> 5132.6886
A47: OPERF: net cash flow (pro-rata share of LP) | B47: =$C$63*B43 -> -150 | C47: =$C$63*C43 -> -150 | D47: =$C$63*D43 -> -150 | E47: =$C$63*E43 -> -150 | F47: =$C$63*F43 -> -150 | G47: =$C$63*G43 -> 249.81451 | H47: =$C$63*H43 -> 237.39193 | I47: =$C$63*I43 -> 225.46625 | ... L47: =$C$63*L43 -> 769.9033
...

Sheet Q4 Analysis
A1: Q4 — EFFECT OF TPG'S FEE CUT (1.50% → 1.35%) ON OPERF
A2: Compares sheet "Q3 Base case" (current terms) with sheet "Q4 Fee cut" (TPG offer). Everything else is held constant.
A4: A. Whole fund ($ millions)
B5: Current (1.50%) | C5: Offer (1.35%) | D5: Change
A6: LP net IRR | B6: ='Q3 Base case'!$C$50 -> 0.15722559 | C6: ='Q4 Fee cut'!$C$50 -> 0.15936141 | D6: =(C6-B6)*10000 -> 21.358143
A7: LP NPV at 15% | B7: ='Q3 Base case'!$C$51 -> 578.21714 | C7: ='Q4 Fee cut'!$C$51 -> 752.97923 | D7: =C7-B7 -> 174.76209
A8: LP distributions (nominal) | B8: ='Q3 Base case'!$C$53 -> 48070.521 | C8: ='Q4 Fee cut'!$C$53 -> 48631.388 | D8: =C8-B8 -> 560.86732
A9: LP multiple (TVPI) | B9: ='Q3 Base case'!$C$54 -> 2.403526 | C9: ='Q4 Fee cut'!$C$54 -> 2.4315694 | D9: =C9-B9 -> 0.028043366
A10: GP management fees (nominal) | B10: ='Q3 Base case'!$C$55 -> 3000 | C10: ='Q4 Fee cut'!$C$55 -> 2700 | D10: =C10-B10 -> -300 | E10: fees fall by 0.15% × $20bn × 10 years
A11: GP carried interest (nominal) | B11: ='Q3 Base case'!$C$56 -> 7017.6302 | C11: ='Q4 Fee cut'!$C$56 -> 7157.847 | D11: =C11-B11 -> 140.21683 | E11: more capital stays invested, so profits and carry rise
A12: PV of management fees | B12: ='Q3 Base case'!$C$57 -> 1731.4752 | C12: ='Q4 Fee cut'!$C$57 -> 1558.3277 | D12: =C12-B12 -> -173.14752
A13: PV of carried interest | B13: ='Q3 Base case'!$C$58 -> 1845.4937 | C13: ='Q4 Fee cut'!$C$58 -> 1884.5797 | D13: =C13-B13 -> 39.08594
A14: PV of total GP compensation | B14: ='Q3 Base case'!$C$59 -> 3576.9689 | C14: ='Q4 Fee cut'!$C$59 -> 3442.9073 | D14: =C14-B14 -> -134.06158
A16: B. OPERF's $750m commitment ($ millions)
A17: OPERF share of the fund | C17: ='Q4 Fee cut'!$C$63 -> 0.0375
A18: Annual management fee — current terms | C18: =Inputs!$C$26*Inputs!$C$18 -> 11.25
A19: Annual management fee — TPG offer | C19: =Inputs!$C$26*Inputs!$C$19 -> 10.125
A20: Annual fee saving | C20: =C18-C19 -> 1.125
A21: Fee saving over the fund life (nominal) | C21: =C20*Inputs!$C$7 -> 11.25
A22: PV of fee saving at 15% (memo) | C22: =C17*(B12-C12) -> 6.4930319
A23: PV of extra distributions (fee dollars stay invested at 20%) | C23: =C17*(NPV(Inputs!$C$9,'Q4 Fee cut'!$C$23:$L$23)-NPV(Inputs!$C$9,'Q3 Base case'!$C$23:$L$23)) -> 8.0193011 | E23: exceeds the PV of fees saved: money left in the fund grows at 20% but is discounted at 15%
A24: Less: PV of extra carried interest paid to TPG | C24: =-C17*(C13-B13) -> -1.4657228 | E24: TPG keeps 20% of the extra profit
A25: Net NPV gain to OPERF | C25: =C23+C24 -> 6.5535783
A26: Check: equals OPERF NPV change between sheets (0 = OK) | C26: =ROUND(C25-('Q4 Fee cut'!$C$64-'Q3 Base case'!$C$64),6) -> 0
A27: Net NPV gain as % of OPERF commitment | C27: =IF(Inputs!$C$26=0,0,C25/Inputs!$C$26) -> 0.0087381044
A28: LP IRR gain | C28: =D6 -> 21.358143
A30: C. Gross-to-net bridge after the fee cut (LP IRR)
B31: Gross | C31: After fees | D31: Net to LPs | E31: Fee drag | F31: Carry drag
A32: Current terms (1.50%) | B32: =Engine!$K$16 -> 0.2 | C32: =Engine!$K$17 -> 0.17804892 | D32: ='Q3 Base case'!$C$50 -> 0.15722559 | E32: =(B32-C32)*10000 -> 219.51075 | F32: =(C32-D32)*10000 -> 208.2333
A33: TPG offer (1.35%) | B33: =Engine!$K$16 -> 0.2 | C33: =Engine!$K$18 -> 0.18034964 | D33: ='Q4 Fee cut'!$C$50 -> 0.15936141 | E33: =(B33-C33)*10000 -> 196.50358 | F33: =(C33-D33)*10000 -> 209.88234
A35: D. Is the gain from the fee cut the same in good and bad outcomes?
A36: Asset growth | B36: LP IRR current | C36: LP IRR offer | D36: Gain (bps) | E36: OPERF NPV gain ($m)
A37: =Engine!$I$21 -> 0 | B37: =Engine!$K$21 -> -0.028740632 | C37: =Engine!$K$52 -> -0.025625198 | D37: =(C37-B37)*10000 -> 31.154342 | E37: =$C$17*(Engine!$L$52-Engine!$L$21) -> 3.5465952
A38: =Engine!$I$26 -> 0.05 | B38: =Engine!$K$26 -> 0.019506054 | C38: =Engine!$K$57 -> 0.021836081 | D38: =(C38-B38)*10000 -> 23.300264 | E38: =$C$17*(Engine!$L$57-Engine!$L$26) -> 3.6349356
A39: =Engine!$I$31 -> 0.1 | B39: =Engine!$K$31 -> 0.064190788 | C39: =Engine!$K$62 -> 0.066474587 | D39: =(C39-B39)*10000 -> 22.83799 | E39: =$C$17*(Engine!$L$62-Engine!$L$31) -> 4.4405712
A40: =Engine!$I$36 -> 0.15 | B40: =Engine!$K$36 -> 0.1104452 | C40: =Engine!$K$67 -> 0.11263957 | D40: =(C40-B40)*10000 -> 21.943758 | E40: =$C$17*(Engine!$L$67-Engine!$L$36) -> 5.3289503
A41: =Engine!$I$41 -> 0.2 | B41: =Engine!$K$41 -> 0.15722559 | C41: =Engine!$K$72 -> 0.15936141 | D41: =(C41-B41)*10000 -> 21.358143 | E41: =$C$17*(Engine!$L$72-Engine!$L$41) -> 6.5535783
A42: =Engine!$I$46 -> 0.25 | B42: =Engine!$K$46 -> 0.20431317 | C42: =Engine!$K$77 -> 0.20638488 | D42: =(C42-B42)*10000 -> 20.717042 | E42: =$C$17*(Engine!$L$77-Engine!$L$46) -> 8.039932
A43: =Engine!$I$51 -> 0.3 | B43: =Engine!$K$51 -> 0.25164567 | C43: =Engine!$K$82 -> 0.25369121 | D43: =(C43-B43)*10000 -> 20.455408 | E43: =$C$17*(Engine!$L$82-Engine!$L$51) -> 9.9944624
A44: The gain is small and similar in every outcome: a transfer from TPG to LPs, not a change in incentives.
...

Sheet Q5a Hard hurdle
A1: OREGON PUBLIC EMPLOYEES RETIREMENT FUND
B2: Committed capital ($ millions) | C2: =Inputs!$C$6 -> 20000 | E2: Asset growth rate (%) | F2: =Inputs!$C$8 -> 0.2 | H2: Hurdle rate (%) | I2: =Inputs!$C$22 -> 0.08
B3: Management fee (%) | C3: =Inputs!$C$19 -> 0.0135 | E3: Discount rate (%) | F3: =Inputs!$C$9 -> 0.15 | H3: GP catch-up (1 = yes) | I3: 0
B4: LP share of profit (%) | C4: =1-F4 -> 0.8 | E4: GP share of profit (%) | F4: =Inputs!$C$20 -> 0.2 | H4: OPERF ($ millions) | I4: =Inputs!$C$26 -> 750
A6: ="Scenario: "&"TPG offer + hard hurdle — "&TEXT(C3,"0.00%")&" fee on committed capital, "&TEXT(F4,"0%")&" carry, "&IF(I2=0,"no hurdle",TEXT(I2,"0%")&" hurdle"&IF(I3=1," with 100% GP catch-up (soft)"," with no catch-up (hard)")) -> Scenario: TPG offer + hard hurdle — 1.35% fee on committed capital, 20% carry, 8% hurdle with no catch-up (hard) | J6: Prep Q5 — 8% hurdle, no catch-up
A8: Year | B8: 0 | C8: 1 | D8: 2 | E8: 3 | F8: 4 | G8: 5 | H8: 6 | I8: 7 | J8: 8 | K8: 9 | L8: 10
A9: Assumptions
A10: % Drawn of committed capital | C10: =Inputs!C$13 -> 0.2 | D10: =Inputs!D$13 -> 0.2 | E10: =Inputs!E$13 -> 0.2 | F10: =Inputs!F$13 -> 0.2 | G10: =Inputs!G$13 -> 0.2 | H10: =Inputs!H$13 -> 0 | I10: =Inputs!I$13 -> 0 | J10: =Inputs!J$13 -> 0 | ... L10: =Inputs!L$13 -> 0
A11: Distribution rate | C11: =Inputs!C$14 -> 0 | D11: =Inputs!D$14 -> 0 | E11: =Inputs!E$14 -> 0 | F11: =Inputs!F$14 -> 0 | G11: =Inputs!G$14 -> 0.2 | H11: =Inputs!H$14 -> 0.2 | I11: =Inputs!I$14 -> 0.2 | J11: =Inputs!J$14 -> 0.2 | ... L11: =Inputs!L$14 -> 1
A13: At the beginning of the year
A14: Assets | C14: =B24 -> 0 | D14: =C24 -> 4476 | E14: =D24 -> 9847.2 | F14: =E24 -> 16292.64 | G14: =F24 -> 24027.168 | H14: =G24 -> 26646.881 | I14: =H24 -> 25321.806 | J14: =I24 -> 24049.734 | ... L14: =K24 -> 21656.203
A15: Plus: Takedown | C15: =$C$2*C10 -> 4000 | D15: =$C$2*D10 -> 4000 | E15: =$C$2*E10 -> 4000 | F15: =$C$2*F10 -> 4000 | G15: =$C$2*G10 -> 4000 | H15: =$C$2*H10 -> 0 | I15: =$C$2*I10 -> 0 | J15: =$C$2*J10 -> 0 | ... L15: =$C$2*L10 -> 0
A16: Less: Management fee | C16: =$C$2*$C$3 -> 270 | D16: =$C$2*$C$3 -> 270 | E16: =$C$2*$C$3 -> 270 | F16: =$C$2*$C$3 -> 270 | G16: =$C$2*$C$3 -> 270 | H16: =$C$2*$C$3 -> 270 | I16: =$C$2*$C$3 -> 270 | J16: =$C$2*$C$3 -> 270 | ... L16: =$C$2*$C$3 -> 270
A17: Invested capital per period | C17: =C14+C15-C16 -> 3730 | D17: =D14+D15-D16 -> 8206 | E17: =E14+E15-E16 -> 13577.2 | F17: =F14+F15-F16 -> 20022.64 | G17: =G14+G15-G16 -> 27757.168 | H17: =H14+H15-H16 -> 26376.881 | I17: =I14+I15-I16 -> 25051.806 | J17: =J14+J15-J16 -> 23779.734 | ... L17: =L14+L15-L16 -> 21386.203
A19: At the end of the year
A20: Plus: Asset growth over year | C20: =C17*$F$2 -> 746 | D20: =D17*$F$2 -> 1641.2 | E20: =E17*$F$2 -> 2715.44 | F20: =F17*$F$2 -> 4004.528 | G20: =G17*$F$2 -> 5551.4336 | H20: =H17*$F$2 -> 5275.3763 | I20: =I17*$F$2 -> 5010.3612 | J20: =J17*$F$2 -> 4755.9468 | ... L20: =L17*$F$2 -> 4277.2405
A21: NAV before distributions | C21: =C17+C20 -> 4476 | D21: =D17+D20 -> 9847.2 | E21: =E17+E20 -> 16292.64 | F21: =F17+F20 -> 24027.168 | G21: =G17+G20 -> 33308.602 | H21: =H17+H20 -> 31652.258 | I21: =I17+I20 -> 30062.167 | J21: =J17+J20 -> 28535.681 | ... L21: =L17+L20 -> 25663.443
A23: Less: Distributions | C23: =C21*C11 -> 0 | D23: =D21*D11 -> 0 | E23: =E21*E11 -> 0 | F23: =F21*F11 -> 0 | G23: =G21*G11 -> 6661.7203 | H23: =H21*H11 -> 6330.4515 | I23: =I21*I11 -> 6012.4334 | J23: =J21*J11 -> 5707.1361 | ... L23: =L21*L11 -> 25663.443
A24: NAV after distributions | C24: =C21-C23 -> 4476 | D24: =D21-D23 -> 9847.2 | E24: =E21-E23 -> 16292.64 | F24: =F21-F23 -> 24027.168 | G24: =G21-G23 -> 26646.881 | H24: =H21-H23 -> 25321.806 | I24: =I21-I23 -> 24049.734 | J24: =J21-J23 -> 22828.544 | ... L24: =L21-L23 -> 0
A26: Distribution waterfall (whole-fund carry: LPs made whole first)
A27: Unreturned LP capital, incl. this year's takedown | C27: =B29+C15 -> 4000 | D27: =C29+D15 -> 8000 | E27: =D29+E15 -> 12000 | F27: =E29+F15 -> 16000 | G27: =F29+G15 -> 20000 | H27: =G29+H15 -> 13338.28 | I27: =H29+I15 -> 7007.8282 | J27: =I29+J15 -> 995.39473 | ... L27: =K29+L15 -> 0
A28: Tier 1 – Return of capital to LPs | C28: =MIN(C23,C27) -> 0 | D28: =MIN(D23,D27) -> 0 | E28: =MIN(E23,E27) -> 0 | F28: =MIN(F23,F27) -> 0 | G28: =MIN(G23,G27) -> 6661.7203 | H28: =MIN(H23,H27) -> 6330.4515 | I28: =MIN(I23,I27) -> 6012.4334 | J28: =MIN(J23,J27) -> 995.39473 | ... L28: =MIN(L23,L27) -> 0
A29: Unreturned LP capital, end of year | C29: =C27-C28 -> 4000 | D29: =D27-D28 -> 8000 | E29: =E27-E28 -> 12000 | F29: =F27-F28 -> 16000 | G29: =G27-G28 -> 13338.28 | H29: =H27-H28 -> 7007.8282 | I29: =I27-I28 -> 995.39473 | J29: =J27-J28 -> 0 | ... L29: =L27-L28 -> 0
A30: Preferred return due (hurdle accrual + unpaid) | C30: =B32+$I$2*(C27+B32) -> 320 | D30: =C32+$I$2*(D27+C32) -> 985.6 | E30: =D32+$I$2*(E27+D32) -> 2024.448 | F30: =E32+$I$2*(F27+E32) -> 3466.4038 | G30: =F32+$I$2*(G27+F32) -> 5343.7161 | H30: =G32+$I$2*(H27+G32) -> 6838.2758 | I30: =H32+$I$2*(I27+H32) -> 7945.9641 | J30: =I32+$I$2*(J27+I32) -> 8661.2728 | ... L30: =K32+$I$2*(L27+K32) -> 0
A31: Tier 2 – Preferred return paid to LPs | C31: =MIN(C23-C28,C30) -> 0 | D31: =MIN(D23-D28,D30) -> 0 | E31: =MIN(E23-E28,E30) -> 0 | F31: =MIN(F23-F28,F30) -> 0 | G31: =MIN(G23-G28,G30) -> 0 | H31: =MIN(H23-H28,H30) -> 0 | I31: =MIN(I23-I28,I30) -> 0 | J31: =MIN(J23-J28,J30) -> 4711.7414 | ... L31: =MIN(L23-L28,L30) -> 0
A32: Unpaid preferred return, end of year | C32: =C30-C31 -> 320 | D32: =D30-D31 -> 985.6 | E32: =E30-E31 -> 2024.448 | F32: =F30-F31 -> 3466.4038 | G32: =G30-G31 -> 5343.7161 | H32: =H30-H31 -> 6838.2758 | I32: =I30-I31 -> 7945.9641 | J32: =J30-J31 -> 3949.5315 | ... L32: =L30-L31 -> 0
A33: Tier 3 – GP catch-up (soft hurdle only) | C33: =IF($I$3=1,MIN(C23-C28-C31,MAX(0,$F$4/(1-$F$4)*(B37+C31)-B38)),0) -> 0 | D33: =IF($I$3=1,MIN(D23-D28-D31,MAX(0,$F$4/(1-$F$4)*(C37+D31)-C38)),0) -> 0 | E33: =IF($I$3=1,MIN(E23-E28-E31,MAX(0,$F$4/(1-$F$4)*(D37+E31)-D38)),0) -> 0 | F33: =IF($I$3=1,MIN(F23-F28-F31,MAX(0,$F$4/(1-$F$4)*(E37+F31)-E38)),0) -> 0 | G33: =IF($I$3=1,MIN(G23-G28-G31,MAX(0,$F$4/(1-$F$4)*(F37+G31)-F38)),0) -> 0 | H33: =IF($I$3=1,MIN(H23-H28-H31,MAX(0,$F$4/(1-$F$4)*(G37+H31)-G38)),0) -> 0 | I33: =IF($I$3=1,MIN(I23-I28-I31,MAX(0,$F$4/(1-$F$4)*(H37+I31)-H38)),0) -> 0 | J33: =IF($I$3=1,MIN(J23-J28-J31,MAX(0,$F$4/(1-$F$4)*(I37+J31)-I38)),0) -> 0 | ... L33: =IF($I$3=1,MIN(L23-L28-L31,MAX(0,$F$4/(1-$F$4)*(K37+L31)-K38)),0) -> 0
A34: Tier 4 – Remaining profit split LP/GP | C34: =C23-C28-C31-C33 -> 0 | D34: =D23-D28-D31-D33 -> 0 | E34: =E23-E28-E31-E33 -> 0 | F34: =F23-F28-F31-F33 -> 0 | G34: =G23-G28-G31-G33 -> 0 | H34: =H23-H28-H31-H33 -> 0 | I34: =I23-I28-I31-I33 -> 0 | J34: =J23-J28-J31-J33 -> 0 | ... L34: =L23-L28-L31-L33 -> 25663.443
A35: Total distributions to LPs | C35: =C28+C31+$C$4*C34 -> 0 | D35: =D28+D31+$C$4*D34 -> 0 | E35: =E28+E31+$C$4*E34 -> 0 | F35: =F28+F31+$C$4*F34 -> 0 | G35: =G28+G31+$C$4*G34 -> 6661.7203 | H35: =H28+H31+$C$4*H34 -> 6330.4515 | I35: =I28+I31+$C$4*I34 -> 6012.4334 | J35: =J28+J31+$C$4*J34 -> 5707.1361 | ... L35: =L28+L31+$C$4*L34 -> 20530.755
A36: Total carried interest to GP | C36: =C33+$F$4*C34 -> 0 | D36: =D33+$F$4*D34 -> 0 | E36: =E33+$F$4*E34 -> 0 | F36: =F33+$F$4*F34 -> 0 | G36: =G33+$F$4*G34 -> 0 | H36: =H33+$F$4*H34 -> 0 | I36: =I33+$F$4*I34 -> 0 | J36: =J33+$F$4*J34 -> 0 | ... L36: =L33+$F$4*L34 -> 5132.6886
A37: Cumulative LP profit received | C37: =B37+C31+$C$4*C34 -> 0 | D37: =C37+D31+$C$4*D34 -> 0 | E37: =D37+E31+$C$4*E34 -> 0 | F37: =E37+F31+$C$4*F34 -> 0 | G37: =F37+G31+$C$4*G34 -> 0 | H37: =G37+H31+$C$4*H34 -> 0 | I37: =H37+I31+$C$4*I34 -> 0 | J37: =I37+J31+$C$4*J34 -> 4711.7414 | ... L37: =K37+L31+$C$4*L34 -> 30426.835
A38: Cumulative GP carried interest | C38: =B38+C36 -> 0 | D38: =C38+D36 -> 0 | E38: =D38+E36 -> 0 | F38: =E38+F36 -> 0 | G38: =F38+G36 -> 0 | H38: =G38+H36 -> 0 | I38: =H38+I36 -> 0 | J38: =I38+J36 -> 0 | ... L38: =K38+L36 -> 5362.4
A40: Cash flows by date (column = point in time t: the start of Year n is t = n − 1; the end of Year n is t = n)
